[2025-01-24T22:28:28.243+0000] {local_task_job_runner.py:123} INFO - ::group::Pre task execution logs
[2025-01-24T22:28:28.251+0000] {taskinstance.py:2613} INFO - Dependencies all met for dep_context=non-requeueable deps ti=<TaskInstance: ETL_toll_data.extract_data_from_csv manual__2025-01-24T22:23:23.517771+00:00 [queued]>
[2025-01-24T22:28:28.254+0000] {taskinstance.py:2613} INFO - Dependencies all met for dep_context=requeueable deps ti=<TaskInstance: ETL_toll_data.extract_data_from_csv manual__2025-01-24T22:23:23.517771+00:00 [queued]>
[2025-01-24T22:28:28.255+0000] {taskinstance.py:2866} INFO - Starting attempt 2 of 2
[2025-01-24T22:28:28.259+0000] {taskinstance.py:2889} INFO - Executing <Task(BashOperator): extract_data_from_csv> on 2025-01-24 22:23:23.517771+00:00
[2025-01-24T22:28:28.264+0000] {warnings.py:112} WARNING - /home/***/.local/lib/python3.12/site-packages/***/task/task_runner/standard_task_runner.py:70: DeprecationWarning: This process (pid=101) is multi-threaded, use of fork() may lead to deadlocks in the child.
  pid = os.fork()

[2025-01-24T22:28:28.265+0000] {standard_task_runner.py:72} INFO - Started process 103 to run task
[2025-01-24T22:28:28.265+0000] {standard_task_runner.py:104} INFO - Running: ['***', 'tasks', 'run', 'ETL_toll_data', 'extract_data_from_csv', 'manual__2025-01-24T22:23:23.517771+00:00', '--job-id', '27', '--raw', '--subdir', 'DAGS_FOLDER/finalassignment/ETL_dag.py', '--cfg-path', '/tmp/tmpdq4bw48f']
[2025-01-24T22:28:28.266+0000] {standard_task_runner.py:105} INFO - Job 27: Subtask extract_data_from_csv
[2025-01-24T22:28:28.293+0000] {task_command.py:467} INFO - Running <TaskInstance: ETL_toll_data.extract_data_from_csv manual__2025-01-24T22:23:23.517771+00:00 [running]> on host 8e8ba4f664ac
[2025-01-24T22:28:28.323+0000] {taskinstance.py:3132} INFO - Exporting env vars: AIRFLOW_CTX_DAG_OWNER='***' AIRFLOW_CTX_DAG_ID='ETL_toll_data' AIRFLOW_CTX_TASK_ID='extract_data_from_csv' AIRFLOW_CTX_EXECUTION_DATE='2025-01-24T22:23:23.517771+00:00' AIRFLOW_CTX_TRY_NUMBER='2' AIRFLOW_CTX_DAG_RUN_ID='manual__2025-01-24T22:23:23.517771+00:00'
[2025-01-24T22:28:28.324+0000] {logging_mixin.py:190} INFO - Task instance is in running state
[2025-01-24T22:28:28.324+0000] {logging_mixin.py:190} INFO -  Previous state of the Task instance: queued
[2025-01-24T22:28:28.324+0000] {logging_mixin.py:190} INFO - Current task name:extract_data_from_csv state:running start_date:2025-01-24 22:28:28.251960+00:00
[2025-01-24T22:28:28.324+0000] {logging_mixin.py:190} INFO - Dag name:ETL_toll_data and current dag run status:running
[2025-01-24T22:28:28.324+0000] {taskinstance.py:731} INFO - ::endgroup::
[2025-01-24T22:28:28.325+0000] {subprocess.py:78} INFO - Tmp dir root location: /tmp
[2025-01-24T22:28:28.325+0000] {subprocess.py:88} INFO - Running command: ['/usr/bin/bash', '-c', "cut -d ',' -f 1,2,3,4 /Users/akshatsharma/Desktop/DeskTop/IBM-Airflow-Dag/dags/finalassignment/tolldata/vehicle-data.csv > /Users/akshatsharma/Desktop/DeskTop/IBM-Airflow-Dag/dags/finalassignment/tolldata/vehicle-data-extracted.csv || { echo 'Command failed'; exit 1; }"]
[2025-01-24T22:28:28.332+0000] {subprocess.py:99} INFO - Output:
[2025-01-24T22:28:28.333+0000] {subprocess.py:106} INFO - /usr/bin/bash: line 1: /Users/akshatsharma/Desktop/DeskTop/IBM-Airflow-Dag/dags/finalassignment/tolldata/vehicle-data-extracted.csv: No such file or directory
[2025-01-24T22:28:28.334+0000] {subprocess.py:106} INFO - Command failed
[2025-01-24T22:28:28.334+0000] {subprocess.py:110} INFO - Command exited with return code 1
[2025-01-24T22:28:28.339+0000] {taskinstance.py:3311} ERROR - Task failed with exception
Traceback (most recent call last):
  File "/home/airflow/.local/lib/python3.12/site-packages/airflow/models/taskinstance.py", line 767, in _execute_task
    result = _execute_callable(context=context, **execute_callable_kwargs)
             ^^^^^^^^^^^^^^^^^^^^^^^^^^^^^^^^^^^^^^^^^^^^^^^^^^^^^^^^^^^^^
  File "/home/airflow/.local/lib/python3.12/site-packages/airflow/models/taskinstance.py", line 733, in _execute_callable
    return ExecutionCallableRunner(
           ^^^^^^^^^^^^^^^^^^^^^^^^
  File "/home/airflow/.local/lib/python3.12/site-packages/airflow/utils/operator_helpers.py", line 252, in run
    return self.func(*args, **kwargs)
           ^^^^^^^^^^^^^^^^^^^^^^^^^^
  File "/home/airflow/.local/lib/python3.12/site-packages/airflow/models/baseoperator.py", line 422, in wrapper
    return func(self, *args, **kwargs)
           ^^^^^^^^^^^^^^^^^^^^^^^^^^^
  File "/home/airflow/.local/lib/python3.12/site-packages/airflow/operators/bash.py", line 276, in execute
    raise AirflowException(
airflow.exceptions.AirflowException: Bash command failed. The command returned a non-zero exit code 1.
[2025-01-24T22:28:28.341+0000] {logging_mixin.py:190} INFO - Task instance in failure state
[2025-01-24T22:28:28.341+0000] {logging_mixin.py:190} INFO - Task start:2025-01-24 22:28:28.251960+00:00 end:2025-01-24 22:28:28.341501+00:00 duration:0.089541
[2025-01-24T22:28:28.342+0000] {logging_mixin.py:190} INFO - Task:<Task(BashOperator): extract_data_from_csv> dag:<DAG: ETL_toll_data> dagrun:<DagRun ETL_toll_data @ 2025-01-24 22:23:23.517771+00:00: manual__2025-01-24T22:23:23.517771+00:00, state:running, queued_at: 2025-01-24 22:23:23.534979+00:00. externally triggered: True>
[2025-01-24T22:28:28.342+0000] {logging_mixin.py:190} INFO - Failure caused by Bash command failed. The command returned a non-zero exit code 1.
[2025-01-24T22:28:28.342+0000] {taskinstance.py:1225} INFO - Marking task as FAILED. dag_id=ETL_toll_data, task_id=extract_data_from_csv, run_id=manual__2025-01-24T22:23:23.517771+00:00, execution_date=20250124T222323, start_date=20250124T222828, end_date=20250124T222828
[2025-01-24T22:28:28.346+0000] {taskinstance.py:340} INFO - ::group::Post task execution logs
[2025-01-24T22:28:28.347+0000] {standard_task_runner.py:124} ERROR - Failed to execute job 27 for task extract_data_from_csv (Bash command failed. The command returned a non-zero exit code 1.; 103)
Traceback (most recent call last):
  File "/home/airflow/.local/lib/python3.12/site-packages/airflow/task/task_runner/standard_task_runner.py", line 117, in _start_by_fork
    ret = args.func(args, dag=self.dag)
          ^^^^^^^^^^^^^^^^^^^^^^^^^^^^^
  File "/home/airflow/.local/lib/python3.12/site-packages/airflow/cli/cli_config.py", line 49, in command
    return func(*args, **kwargs)
           ^^^^^^^^^^^^^^^^^^^^^
  File "/home/airflow/.local/lib/python3.12/site-packages/airflow/utils/cli.py", line 116, in wrapper
    return f(*args, **kwargs)
           ^^^^^^^^^^^^^^^^^^
  File "/home/airflow/.local/lib/python3.12/site-packages/airflow/cli/commands/task_command.py", line 483, in task_run
    task_return_code = _run_task_by_selected_method(args, _dag, ti)
                       ^^^^^^^^^^^^^^^^^^^^^^^^^^^^^^^^^^^^^^^^^^^^
  File "/home/airflow/.local/lib/python3.12/site-packages/airflow/cli/commands/task_command.py", line 256, in _run_task_by_selected_method
    return _run_raw_task(args, ti)
           ^^^^^^^^^^^^^^^^^^^^^^^
  File "/home/airflow/.local/lib/python3.12/site-packages/airflow/cli/commands/task_command.py", line 341, in _run_raw_task
    return ti._run_raw_task(
           ^^^^^^^^^^^^^^^^^
  File "/home/airflow/.local/lib/python3.12/site-packages/airflow/utils/session.py", line 97, in wrapper
    return func(*args, session=session, **kwargs)
           ^^^^^^^^^^^^^^^^^^^^^^^^^^^^^^^^^^^^^^
  File "/home/airflow/.local/lib/python3.12/site-packages/airflow/models/taskinstance.py", line 3005, in _run_raw_task
    return _run_raw_task(
           ^^^^^^^^^^^^^^
  File "/home/airflow/.local/lib/python3.12/site-packages/airflow/models/taskinstance.py", line 273, in _run_raw_task
    TaskInstance._execute_task_with_callbacks(
  File "/home/airflow/.local/lib/python3.12/site-packages/airflow/models/taskinstance.py", line 3159, in _execute_task_with_callbacks
    result = self._execute_task(context, task_orig)
             ^^^^^^^^^^^^^^^^^^^^^^^^^^^^^^^^^^^^^^
  File "/home/airflow/.local/lib/python3.12/site-packages/airflow/models/taskinstance.py", line 3183, in _execute_task
    return _execute_task(self, context, task_orig)
           ^^^^^^^^^^^^^^^^^^^^^^^^^^^^^^^^^^^^^^^
  File "/home/airflow/.local/lib/python3.12/site-packages/airflow/models/taskinstance.py", line 767, in _execute_task
    result = _execute_callable(context=context, **execute_callable_kwargs)
             ^^^^^^^^^^^^^^^^^^^^^^^^^^^^^^^^^^^^^^^^^^^^^^^^^^^^^^^^^^^^^
  File "/home/airflow/.local/lib/python3.12/site-packages/airflow/models/taskinstance.py", line 733, in _execute_callable
    return ExecutionCallableRunner(
           ^^^^^^^^^^^^^^^^^^^^^^^^
  File "/home/airflow/.local/lib/python3.12/site-packages/airflow/utils/operator_helpers.py", line 252, in run
    return self.func(*args, **kwargs)
           ^^^^^^^^^^^^^^^^^^^^^^^^^^
  File "/home/airflow/.local/lib/python3.12/site-packages/airflow/models/baseoperator.py", line 422, in wrapper
    return func(self, *args, **kwargs)
           ^^^^^^^^^^^^^^^^^^^^^^^^^^^
  File "/home/airflow/.local/lib/python3.12/site-packages/airflow/operators/bash.py", line 276, in execute
    raise AirflowException(
airflow.exceptions.AirflowException: Bash command failed. The command returned a non-zero exit code 1.
[2025-01-24T22:28:28.368+0000] {local_task_job_runner.py:266} INFO - Task exited with return code 1
[2025-01-24T22:28:28.374+0000] {local_task_job_runner.py:245} INFO - ::endgroup::
