[2025-01-24T22:35:58.037+0000] {local_task_job_runner.py:123} INFO - ::group::Pre task execution logs
[2025-01-24T22:35:58.046+0000] {taskinstance.py:2613} INFO - Dependencies all met for dep_context=non-requeueable deps ti=<TaskInstance: ETL_toll_data.extract_data_from_csv manual__2025-01-24T22:35:53.870034+00:00 [queued]>
[2025-01-24T22:35:58.050+0000] {taskinstance.py:2613} INFO - Dependencies all met for dep_context=requeueable deps ti=<TaskInstance: ETL_toll_data.extract_data_from_csv manual__2025-01-24T22:35:53.870034+00:00 [queued]>
[2025-01-24T22:35:58.051+0000] {taskinstance.py:2866} INFO - Starting attempt 1 of 2
[2025-01-24T22:35:58.057+0000] {taskinstance.py:2889} INFO - Executing <Task(BashOperator): extract_data_from_csv> on 2025-01-24 22:35:53.870034+00:00
[2025-01-24T22:35:58.064+0000] {warnings.py:112} WARNING - /home/***/.local/lib/python3.12/site-packages/***/task/task_runner/standard_task_runner.py:70: DeprecationWarning: This process (pid=82) is multi-threaded, use of fork() may lead to deadlocks in the child.
  pid = os.fork()

[2025-01-24T22:35:58.065+0000] {standard_task_runner.py:72} INFO - Started process 91 to run task
[2025-01-24T22:35:58.066+0000] {standard_task_runner.py:104} INFO - Running: ['***', 'tasks', 'run', 'ETL_toll_data', 'extract_data_from_csv', 'manual__2025-01-24T22:35:53.870034+00:00', '--job-id', '31', '--raw', '--subdir', 'DAGS_FOLDER/finalassignment/ETL_dag.py', '--cfg-path', '/tmp/tmp1d9b9vjx']
[2025-01-24T22:35:58.067+0000] {standard_task_runner.py:105} INFO - Job 31: Subtask extract_data_from_csv
[2025-01-24T22:35:58.098+0000] {task_command.py:467} INFO - Running <TaskInstance: ETL_toll_data.extract_data_from_csv manual__2025-01-24T22:35:53.870034+00:00 [running]> on host 840d1435b6f8
[2025-01-24T22:35:58.147+0000] {taskinstance.py:3132} INFO - Exporting env vars: AIRFLOW_CTX_DAG_OWNER='***' AIRFLOW_CTX_DAG_ID='ETL_toll_data' AIRFLOW_CTX_TASK_ID='extract_data_from_csv' AIRFLOW_CTX_EXECUTION_DATE='2025-01-24T22:35:53.870034+00:00' AIRFLOW_CTX_TRY_NUMBER='1' AIRFLOW_CTX_DAG_RUN_ID='manual__2025-01-24T22:35:53.870034+00:00'
[2025-01-24T22:35:58.148+0000] {logging_mixin.py:190} INFO - Task instance is in running state
[2025-01-24T22:35:58.148+0000] {logging_mixin.py:190} INFO -  Previous state of the Task instance: queued
[2025-01-24T22:35:58.148+0000] {logging_mixin.py:190} INFO - Current task name:extract_data_from_csv state:running start_date:2025-01-24 22:35:58.047098+00:00
[2025-01-24T22:35:58.148+0000] {logging_mixin.py:190} INFO - Dag name:ETL_toll_data and current dag run status:running
[2025-01-24T22:35:58.148+0000] {taskinstance.py:731} INFO - ::endgroup::
[2025-01-24T22:35:58.149+0000] {subprocess.py:78} INFO - Tmp dir root location: /tmp
[2025-01-24T22:35:58.149+0000] {subprocess.py:88} INFO - Running command: ['/usr/bin/bash', '-c', "cut -d ',' -f 1,2,3,4 /Users/akshatsharma/Desktop/DeskTop/IBM-Airflow-Dag/dags/finalassignment/tolldata/vehicle-data.csv > /Users/akshatsharma/Desktop/DeskTop/IBM-Airflow-Dag/dags/finalassignment/tolldata/vehicle-data-extracted.csv || { echo 'Command failed'; exit 1; }"]
[2025-01-24T22:35:58.159+0000] {subprocess.py:99} INFO - Output:
[2025-01-24T22:35:58.161+0000] {subprocess.py:106} INFO - /usr/bin/bash: line 1: /Users/akshatsharma/Desktop/DeskTop/IBM-Airflow-Dag/dags/finalassignment/tolldata/vehicle-data-extracted.csv: No such file or directory
[2025-01-24T22:35:58.162+0000] {subprocess.py:106} INFO - Command failed
[2025-01-24T22:35:58.162+0000] {subprocess.py:110} INFO - Command exited with return code 1
[2025-01-24T22:35:58.170+0000] {taskinstance.py:3311} ERROR - Task failed with exception
Traceback (most recent call last):
  File "/home/airflow/.local/lib/python3.12/site-packages/airflow/models/taskinstance.py", line 767, in _execute_task
    result = _execute_callable(context=context, **execute_callable_kwargs)
             ^^^^^^^^^^^^^^^^^^^^^^^^^^^^^^^^^^^^^^^^^^^^^^^^^^^^^^^^^^^^^
  File "/home/airflow/.local/lib/python3.12/site-packages/airflow/models/taskinstance.py", line 733, in _execute_callable
    return ExecutionCallableRunner(
           ^^^^^^^^^^^^^^^^^^^^^^^^
  File "/home/airflow/.local/lib/python3.12/site-packages/airflow/utils/operator_helpers.py", line 252, in run
    return self.func(*args, **kwargs)
           ^^^^^^^^^^^^^^^^^^^^^^^^^^
  File "/home/airflow/.local/lib/python3.12/site-packages/airflow/models/baseoperator.py", line 422, in wrapper
    return func(self, *args, **kwargs)
           ^^^^^^^^^^^^^^^^^^^^^^^^^^^
  File "/home/airflow/.local/lib/python3.12/site-packages/airflow/operators/bash.py", line 276, in execute
    raise AirflowException(
airflow.exceptions.AirflowException: Bash command failed. The command returned a non-zero exit code 1.
[2025-01-24T22:35:58.175+0000] {logging_mixin.py:190} INFO - Task instance in failure state
[2025-01-24T22:35:58.175+0000] {logging_mixin.py:190} INFO - Task start:2025-01-24 22:35:58.047098+00:00 end:2025-01-24 22:35:58.174992+00:00 duration:0.127894
[2025-01-24T22:35:58.175+0000] {logging_mixin.py:190} INFO - Task:<Task(BashOperator): extract_data_from_csv> dag:<DAG: ETL_toll_data> dagrun:<DagRun ETL_toll_data @ 2025-01-24 22:35:53.870034+00:00: manual__2025-01-24T22:35:53.870034+00:00, state:running, queued_at: 2025-01-24 22:35:53.897720+00:00. externally triggered: True>
[2025-01-24T22:35:58.176+0000] {logging_mixin.py:190} INFO - Failure caused by Bash command failed. The command returned a non-zero exit code 1.
[2025-01-24T22:35:58.176+0000] {taskinstance.py:1225} INFO - Marking task as UP_FOR_RETRY. dag_id=ETL_toll_data, task_id=extract_data_from_csv, run_id=manual__2025-01-24T22:35:53.870034+00:00, execution_date=20250124T223553, start_date=20250124T223558, end_date=20250124T223558
[2025-01-24T22:35:58.184+0000] {taskinstance.py:340} INFO - ::group::Post task execution logs
[2025-01-24T22:35:58.184+0000] {standard_task_runner.py:124} ERROR - Failed to execute job 31 for task extract_data_from_csv (Bash command failed. The command returned a non-zero exit code 1.; 91)
Traceback (most recent call last):
  File "/home/airflow/.local/lib/python3.12/site-packages/airflow/task/task_runner/standard_task_runner.py", line 117, in _start_by_fork
    ret = args.func(args, dag=self.dag)
          ^^^^^^^^^^^^^^^^^^^^^^^^^^^^^
  File "/home/airflow/.local/lib/python3.12/site-packages/airflow/cli/cli_config.py", line 49, in command
    return func(*args, **kwargs)
           ^^^^^^^^^^^^^^^^^^^^^
  File "/home/airflow/.local/lib/python3.12/site-packages/airflow/utils/cli.py", line 116, in wrapper
    return f(*args, **kwargs)
           ^^^^^^^^^^^^^^^^^^
  File "/home/airflow/.local/lib/python3.12/site-packages/airflow/cli/commands/task_command.py", line 483, in task_run
    task_return_code = _run_task_by_selected_method(args, _dag, ti)
                       ^^^^^^^^^^^^^^^^^^^^^^^^^^^^^^^^^^^^^^^^^^^^
  File "/home/airflow/.local/lib/python3.12/site-packages/airflow/cli/commands/task_command.py", line 256, in _run_task_by_selected_method
    return _run_raw_task(args, ti)
           ^^^^^^^^^^^^^^^^^^^^^^^
  File "/home/airflow/.local/lib/python3.12/site-packages/airflow/cli/commands/task_command.py", line 341, in _run_raw_task
    return ti._run_raw_task(
           ^^^^^^^^^^^^^^^^^
  File "/home/airflow/.local/lib/python3.12/site-packages/airflow/utils/session.py", line 97, in wrapper
    return func(*args, session=session, **kwargs)
           ^^^^^^^^^^^^^^^^^^^^^^^^^^^^^^^^^^^^^^
  File "/home/airflow/.local/lib/python3.12/site-packages/airflow/models/taskinstance.py", line 3005, in _run_raw_task
    return _run_raw_task(
           ^^^^^^^^^^^^^^
  File "/home/airflow/.local/lib/python3.12/site-packages/airflow/models/taskinstance.py", line 273, in _run_raw_task
    TaskInstance._execute_task_with_callbacks(
  File "/home/airflow/.local/lib/python3.12/site-packages/airflow/models/taskinstance.py", line 3159, in _execute_task_with_callbacks
    result = self._execute_task(context, task_orig)
             ^^^^^^^^^^^^^^^^^^^^^^^^^^^^^^^^^^^^^^
  File "/home/airflow/.local/lib/python3.12/site-packages/airflow/models/taskinstance.py", line 3183, in _execute_task
    return _execute_task(self, context, task_orig)
           ^^^^^^^^^^^^^^^^^^^^^^^^^^^^^^^^^^^^^^^
  File "/home/airflow/.local/lib/python3.12/site-packages/airflow/models/taskinstance.py", line 767, in _execute_task
    result = _execute_callable(context=context, **execute_callable_kwargs)
             ^^^^^^^^^^^^^^^^^^^^^^^^^^^^^^^^^^^^^^^^^^^^^^^^^^^^^^^^^^^^^
  File "/home/airflow/.local/lib/python3.12/site-packages/airflow/models/taskinstance.py", line 733, in _execute_callable
    return ExecutionCallableRunner(
           ^^^^^^^^^^^^^^^^^^^^^^^^
  File "/home/airflow/.local/lib/python3.12/site-packages/airflow/utils/operator_helpers.py", line 252, in run
    return self.func(*args, **kwargs)
           ^^^^^^^^^^^^^^^^^^^^^^^^^^
  File "/home/airflow/.local/lib/python3.12/site-packages/airflow/models/baseoperator.py", line 422, in wrapper
    return func(self, *args, **kwargs)
           ^^^^^^^^^^^^^^^^^^^^^^^^^^^
  File "/home/airflow/.local/lib/python3.12/site-packages/airflow/operators/bash.py", line 276, in execute
    raise AirflowException(
airflow.exceptions.AirflowException: Bash command failed. The command returned a non-zero exit code 1.
[2025-01-24T22:35:58.209+0000] {local_task_job_runner.py:266} INFO - Task exited with return code 1
[2025-01-24T22:35:58.230+0000] {taskinstance.py:3895} INFO - 0 downstream tasks scheduled from follow-on schedule check
[2025-01-24T22:35:58.231+0000] {local_task_job_runner.py:245} INFO - ::endgroup::
